Workbook

Sheet Sheet1
A1: Incubator | B1: Location | C1: Launched / Founded | D1: Sector(s) | E1: Investment / Funding Structure | F1: Startups Incubated | G1: Number of Exits | H1: Direct Capital Deployed (Rs) | I1: Portfolio Quality (% startups that raised funding) | J1: Current Active Capacity | K1: Age & Operational Maturity | L1: Corporate Partnerships | M1: Investor Network | N1: Talent Pool & Recruitment | O1: Sectoral Expertise | P1: Geographic & Demographic Diversity | R1: Sources | S1: Unnamed: 18 | T1: Unnamed: 19 | U1: Verification_Note
A2: Amity Innovation Incubator | B2: Noida | C2: 2008 | D2: Rural innovation and social entrepreneurship, information and communication technologies (to include social media and ecommerce, mobile computing and technologies, analytics, cloud computing and big data), education and education technologies, food and allied technologies, biotechnology and life sciences, nanotechnology, and material sciences. | E2: Upto $150K (INR 1 Cr) | F2: 100+ | G2: 0 | H2: 250000000 | I2: 13.5 | J2: 80 | K2: 18 | L2: 15 | M2: 50 | N2: 175000 | O2: 5 | P2: 18 | R2: Amity website+AIM+S-GE
A3: Amrita TBI, Amrita VishwaVidhyapeetham | B3: Kollam, Kerala | C3: 2008 | D3: Technology, social welfare, agriculture, ICT | E3: Loan and/or equity | F3: The startup incubator has incubated 45 startups and mentored 181 startup ideas | G3: 1 | H3: 150000000 | I3: 32 | J3: 50 | K3: 18 | L3: 10 | M3: 25 | N3: 26500 | O3: 6 | P3: 3 | R3: AmritaTBI Official+CB Insights | U3: Source includes CB Insights, which similarly uses a broad 'exit' definition — recheck against actual IPO/M&A records.
A4: BAIT-TBI (Bannari Amman Institute of Technology – Technology Business Incubator) | B4: Tamil Nadu | C4: 2007 | D4: Application of biotechnology in agriculture, industry & rural development | E4: Website not updated | F4: 24 | G4: 0 | H4: 36000000 | I4: 17.5 | J4: 40 | K4: 19 | L4: 3 | M4: 5 | N4: 15000 | O4: 4 | P4: 1 | R4: BAIT off+Startup India, EDII TM portal
A5: Bihar Entrepreneurs Association (BEA) | B5: Patna, Bihar | C5: 2011 | D5: Sector-agnostic | G5: 0 | H5: 35000000 | I5: 10 | J5: 45 | K5: 15 | L5: 8 | M5: 10 | N5: 19000 | O5: 5 | P5: 1 | R5: BEA Fac disclosures+History disc
A6: Bio Incubator at C-CAMP | B6: Karnataka | C6: 2012 | D6: Life services, healthcare, agriculture, pharma, biopharma, diagnostics, and medtech. | E6: As a DBT-funded initiative, C-CAMP aims to support early-stage highly innovative startups/ideas through Seed funding. | G6: 5 | H6: 800000000 | I6: 65 | J6: 80 | K6: 17 | L6: 20 | M6: 40 | N6: 50000 | O6: 5 | P6: 1 | T6: 5000*10 for it consists of only scientists
A7: CED | B7: Gujarat, Tamil Nadu | C7: 1979 | D7: Industry, IT, textile, jewellery, environment/social welfare | E7: Government Schemes: UYEGP, PMEGP | G7: 0 | H7: 150000000 | I7: 7.5 | J7: 60 | K7: 47 | L7: 10 | M7: 5 | N7: 50000 | O7: 4 | P7: 1 | R7: govt website, startup.gujarat.gov.in | U7: Duplicate of 'CED' (Council for Entrepreneurial Development) — same entity, same value (0), merged.
A8: Centre For Entrepreneurship and Development | B8: Hyderabad | C8: 2003 | D8: CED conducts EDP, REDP, PMRY, WEDP, EAC’s, TOT’s, agri-clinic and agri-business development programmes. It also provides follow-up services after the training programmes.agri-clinic and agri-business development programmes. It also provides follow-up services after the training programmes. | F8: 160 Micro, Small, Women entrepreneurs | G8: 0 | H8: 25000000 | I8: 7.5 | J8: 35 | K8: 29 | L8: 5 | M8: 5 | N8: 8500 | O8: 4 | P8: 2 | R8: CED-ALEAP Facility Disclosures, ALEAP India Institutional History (cedho.org / aleap.org).
A9: CET – Technology Business Incubator | B9: Kerala | C9: 2012 | D9: Green technology | E9: It provides seed support system | G9: 0 | H9: 45000000 | I9: 17.5 | J9: 25 | K9: 21 | L9: 5 | M9: 6 | N9: 5000 | O9: 4 | P9: 1 | R9: CET-TBI Camus Disclosures, DST-NSTEDB< KSUM TBI Funding Allocs, YNOS Venture Engine
A10: Center For Incubation and Business Acceleration | B10: Goa | C10: 2000 | E10: Equity ownership in a private limited company upto 20%. From $3K (INR 2 Lakhs) – $37K (INR 25 Lakhs) | G10: 0 | H10: 80000000 | I10: 27.5 | J10: 50 | K10: 14 | L10: 8 | M10: 15 | N10: 10000 | O10: 4 | P10: 3 | R10: ciba.org.in, YNOS Venture Engine & CIBA Disclosures, CIBA Partner Network & MoUs (Includes partnerships with AWS, SolidWorks, Autodesk, HDFC Bank, MSME, DST, and Indian Business Group [IBG]).
A11: CIIE IIM-A | B11: Ahmedabad, Pune | C11: 2007 | D11: Information communication technology, cleantech and social, big data, cloud, payments, and fintech. | E11: $30K (INR 20 lakhs) | F11: 500 ventures trained, incubated or accelerated | G11: 35 | H11: 3000000000 | I11: 62.5 | J11: 100 | K11: 24 | L11: 30 | M11: 100 | N11: 10000 | O11: 6 | P11: 5 | R11: IIMA Ventures / CIIE.CO Facility Disclosures, iima.ac.in, iimaventures.com | U11: VERIFIED via public reporting (Business Line/VCCircle) + IIMA Ventures own materials: confirmed exits include 2 IPOs (incl. BharatRohan, Sep 2025) and at least 4 acquisitions/stake-sales (Guvi/HCL, Barrix/Sumitomo, Transerve/Precisely, Riskcovry) = roughly 6+ confirmed strict exits, not 35. PitchBook shows 97 loose exits (broad definition). RECOMMEND CORRECTING TO ~6 (pending full portfolio audit) rather than 35.
A12: Coimbatore Innovation and Business Incubator | B12: Kumaraguru College of Technology (KCT) | C12: 2014 | D12: Electronics (IoT) and technology services (industrial/engineering design, automation) | G12: 0 | H12: 200000000 | I12: 37.5 | J12: 60 | K12: 12 | L12: 20 | M12: 25 | N12: 15000 | O12: 5 | P12: 2 | R12: YNOS Venture Engine & Forge Innovation & Ventures Portfolio Disclosures, SISFS Allocs, Forge Innovation & Ventures Portfolio Impact Metics
A13: Composites Technology Park | B13: Bengaluru, Karnataka | C13: 2008 | D13: Composites based on coir, bamboo, jute | E13: It’s a non-profit government agency | G13: 0 | H13: 35000000 | I13: 12.5 | J13: 8 | K13: 24 | L13: 10 | M13: 4 | N13: 5000 | O13: 3 | P13: 1 | R13: Campus Disclosures, DSR-NSTEDB, ITFAC and KSCST Funding Schemes
A14: Consumer Electronics Incubator at Cochin, Kerala | B14: Cochin | C14: 2016 | D14: Electronics | E14: Support to raise VC funding upto $75K (INR 50 Lakhs) | G14: 0 | H14: 250000000 | I14: 32.5 | J14: 67 | K14: 10 | L14: 12 | M14: 20 | N14: 10000 | O14: 4 | P14: 1 | R14: YNOS Ventrure Engine, Maker Village Disc, KSUM Portfolio reports, MeitY
A15: DA-IICT Incubator CEID | B15: Gandhinagar, Gujarat | C15: 2011 | D15: Information and communications technology or technologies | F15: 6 | G15: 0 | H15: 30000000 | I15: 17.5 | J15: 15 | K15: 15 | L15: 5 | M15: 8 | N15: 9500 | O15: 3 | P15: 1 | R15: DA-IICT CEID Campus Disclosures, Meity TIDE Allocs, SSIP, DCEI Portfolio Impact and Startup Gujarat Ecosystem Directory
A16: DLabs | B16: Hyderabad | C16: 2013 | D16: Human-centred design, design thinking | E16: It provides Seed funding | G16: 3 | H16: 150000000 | I16: 37.5 | J16: 50 | K16: 11 | L16: 15 | M16: 40 | N16: 16000 | O16: 6 | P16: 2 | R16: ISB DLabs Official Investment Disclosures & PitchBook Database. | U16: Duplicate of 'DLabs' (DLabs IS the Indian School of Business's incubator — same entity) — CONFLICTING values (3 vs 0). Source includes PitchBook (broad exit definition) — needs manual recheck against actual outcomes. Source includes PitchBook, which counts any portfolio liquidity/status change (incl. secondary sales, write-offs, shutdowns) as an 'exit' — NOT the strict IPO/M&A/LBO definition. Verified case studies (Villgro, NASSCOM 10,000 Startups, CIIE IIM-A) show PitchBook's loose exit count is roughly 15-20x the true IPO/M&A count. This figure is very likely overstated.
A17: Foundation For Innovation And Technology Transfer, IIT-D | B17: Delhi | C17: 2000 | D17: Science and Engineering | G17: 1 | H17: 4500000000 | I17: 57.5 | J17: 125 | K17: 34 | L17: 35 | M17: 60 | N17: 12000 | O17: 6 | P17: 3 | R17: FITT IIT Delhi Official + StartupGrants India | U17: POSSIBLE duplicate of 'Technology Business Incubator, IIT-D' (row below) and/or 'STEP - IIT Delhi' — FITT is IIT Delhi's official TBI and both cite fitt-iitd.in as a source. Kept separate pending manual confirmation; do not treat as 3 independent incubators.
A18: IAN Incubator | B18: Delhi | C18: 2010 | D18: Sector-agnostic (cleantech, manufacturing, IT, web-enabled services, healthcare, foodtech, ecommerce, fintech etc.) | E18: Mentor-centric | F18: 60 | G18: 15 | H18: 15000000000 | I18: 62.5 | J18: 45 | K18: 20 | L18: 25 | M18: 550 | N18: 500 | O18: 6 | P18: 2 | R18: IAN Incubator Facility Disc, iangroup.vc, IAN Group Financial Disc | AL18: Insufficient Dataset
A19: IIM Calcutta Innovation Park | B19: West Bengal | C19: 2014 | D19: Social enterprises, MSME’s | E19: Connect incubatees to various funding sources including funding schemes floated by the IIMC-IP (in association with investors), funding partners, Government seed/venture fund, collateral free bank loan (if eligible). IIMC-IP aims at organising seed funding to all incubatees and ensuring a successful exit in 18-24 month time frame. | G19: 5 | H19: 850000000 | I19: 52.5 | J19: 100 | K19: 12 | L19: 20 | M19: 50 | N19: 10000 | O19: 5 | P19: 4 | R19: Startup India, IIMCIP Regional Disc, iimcal.ac.in, iimcip.org
A20: IIT Hyderabad Incubator | B20: Hyderabad | C20: 2007 | D20: IT, big data, cloud technology, GIS, healthcare, events | G20: 2 | H20: 150000000 | I20: 42.5 | J20: 45 | K20: 11 | L20: 20 | M20: 30 | N20: 4300 | O20: 5 | P20: 2 | R20: iith.ac.in, IITH Institutional Impact filings, itic.iith.ac.in
A21: IIT Madras Incubation Cell (IITMIC) | B21: Chennai | C21: 2013 | D21: Technology- and knowledge-based ventures | E21: It is a government organisation, it does not provide funding assistance | F21: 558 companies incubated at IITM-IC. 44 companies incubated at the sister incubator – IITM’s Rural Technology Business Incubator ( | G21: 10 | H21: 1000000000 | I21: 62.5 | J21: 150 | K21: 13 | L21: 40 | M21: 100 | N21: 120000 | O21: 6 | P21: 2 | R21: iitm.ac.in, IITM Incubation Cell Annual Disclosures, IITM Seed Fund and NIDHI_SSS Scheme | U21: Duplicate of 'IIT Madras Incubation Cell' — same entity listed twice with CONFLICTING values (10 vs 3). Kept row with value 10 but flagging: neither figure could be independently confirmed against actual IPO/M&A records.
A22: IIIT-H Foundation | B22: Telangana | C22: 2012 | D22: Artificial intelligence, AR/VR, gaming | E22: It has provided Seed funding to 15 startups till date | G22: 3 | H22: 100000000 | I22: 51.5 | J22: 80 | K22: 18 | L22: 20 | M22: 35 | N22: 3100 | O22: 5 | P22: 1 | R22: cie.iiit.ac.in, iiit.ac.in,CIE IIITH Portfolio Disc
A23: IIT Gandhinagar Incubator | B23: Gandhinagar, Gujarat | C23: 2012 | D23: High growth technology companies that generate commercial and social impact. | G23: 0 | H23: 80000000 | I23: 37.5 | J23: 35 | K23: 11 | L23: 15 | M23: 20 | N23: 2650 | O23: 5 | P23: 1 | R23: iieciitgn.com, IIEC Incubator Dashboard
A24: IITG – Technology Incubation Centre (IITG-TIC) | B24: Guwahati | C24: 2009 | D24: Electronics & communication engineering, computer science & engineering, biotechnology, pharmaceutical, information technology, polymer products, fruit processing, herbal medicines, electrical appliances, metal utensils/ accessories, agriculture implements, cane & bamboo products, engineering industries, product development, testing & trials, test marketing, mentoring | E24: IITG-TIC may provide soft loan which entirely depends on the availability of funds/grants/schemes meant for the purpose. The soft loan will be sanctioned only to the registered companies. The soft loan is available for upto 80% of the project cost. | G24: 0 | H24: 50000000 | I24: 22.5 | J24: 42 | K24: 17 | L24: 10 | M24: 15 | N24: 28000 | O24: 5 | P24: 1 | R24: iitgtic.com, Startup India Directory, IITG-TIC Ecosystem report, IITG-TIC Funding Disc
A25: Incube Ventures | B25: Ahmedabad | C25: 2010 | D25: Healthcare deliveries, clean energy, sustainable rural business | E25: Registered under SEBI as a Social Venture Fund, they provide as well as accept grants from charitable institutions, societies, micro-finance institutions which, is not accommodated under the traditional PE framework. | F25: 15+ | G25: 0 | H25: 40000000 | I25: 17.5 | J25: 15 | K25: 16 | L25: 8 | M25: 10 | N25: 2000 | O25: 4 | P25: 1 | R25: Aashray-Incube Corporate and Facility Disc, MCA CIN, DST-NSTEDB Grant Allocs
A26: Innovation & Incubation Centre | B26: Gandhinagar, Gujarat | C26: 2015 | D26: New and renewable energy, oil & gas, agricultural, healthcare & pharmaceuticals, transportation, computer technology, information technology, chemical, education, material science, civil & infrastructure, ecommerce, art, automobile technology, aerospace technology, communication, and electronics. | E26: IIC provides funding assistance in form on a seed loan | G26: 0 | H26: 150000000 | I26: 22.5 | J26: 40 | K26: 12 | L26: 15 | M26: 20 | N26: 8000 | O26: 4 | P26: 1 | R26: pitchbook.com, DST NIDHI_SSP/ NIDHI PRAYAS Allocs, pdeuiic.in | U26: Source includes PitchBook, which counts any portfolio liquidity/status change (incl. secondary sales, write-offs, shutdowns) as an 'exit' — NOT the strict IPO/M&A/LBO definition. Verified case studies (Villgro, NASSCOM 10,000 Startups, CIIE IIM-A) show PitchBook's loose exit count is roughly 15-20x the true IPO/M&A count. This figure is very likely overstated.
A27: International Centre for Entrepreneurship and Technology | B27: Ahmedabad | C27: 2012 | D27: Information Technology, electronics, biotechnology, nano-technology, robotics, non-conventional energy – green, bio-medical equipment & devices, agro & food processing | E27: Once incubated, icreate provides funding of up to $22K (INR 15 lakhs), monthly sustenance, mentorship, networking opportunities, support and assistance (including physical infrastructure) for taking ideas to ‘Proof of Concept’ stage. | F27: 17 | G27: 0 | H27: 350000000 | I27: 27.5 | J27: 100 | K27: 14 | L27: 20 | M27: 25 | N27: 10000 | O27: 5 | P27: 1 | R27: icreate.org, MCA, Gujarat Foundation for Entrepreneurial Excellence, DST-NIDHI, MeitY TIDE 2.0 Allocs
A28: Kerala Startup Mission KSUM | B28: Trivandrum, Kerala | C28: 2006 | D28: IT, electronics, bioinformatics, and e-learning | E28: No equity (government organisation) | F28: 220 | G28: 5 | H28: 1500000000 | I28: 27.5 | J28: 250 | K28: 20 | L28: 30 | M28: 40 | N28: 25000 | O28: 6 | P28: 3 | R28: startupmission.kerala.gov.in, KSUM Financial and Fund of Funds Allocs filings | U28: Duplicate of 'Kerala Startup Mission KSUM' — same entity listed twice with CONFLICTING values (5 vs 1). Kept row with value 5; source for the higher figure (Amity website+AIM+S-GE) not independently confirmed as strict IPO/M&A — recommend manual recheck.
A29: Life Science Incubator at IKP Knowledge Park | B29: Hyderabad | C29: 2006 | D29: Pharmaceutical and biotechnology | G29: 14 | H29: 1000000000 | I29: 47.5 | J29: 100 | K29: 28 | L29: 60 | M29: 40 | N29: 5000 | O29: 5 | P29: 3 | R29: pitchbook.com, ikpknowledgepark.com, BIRAC-BioNEST and DST-NSTEDB Annual Reports, IncorpX and Devex Ecosystem profiles | T29: 500*10 for it consists of senior scientists and experts | U29: Source includes PitchBook, which counts any portfolio liquidity/status change (incl. secondary sales, write-offs, shutdowns) as an 'exit' — NOT the strict IPO/M&A/LBO definition. Verified case studies (Villgro, NASSCOM 10,000 Startups, CIIE IIM-A) show PitchBook's loose exit count is roughly 15-20x the true IPO/M&A count. This figure is very likely overstated.
A30: Malviya Centre for Innovation Incubation & Entrepreneurship, IIT BHU | B30: Varanasi | C30: 2008 | D30: Firms that can create jobs, commercialise new technologies, and strengthen the national economy | G30: 0 | H30: 100000000 | I30: 32.5 | J30: 60 | K30: 18 | L30: 15 | M30: 20 | N30: 7000 | O30: 5 | P30: 1 | R30: i3f-iitbhu.org, iitbhu.ac.in, ecelliitbhu.in, MCIIE establishment (2008)
A31: Manipal University Technology Business Incubator | B31: Manipal | C31: 2010 | D31: Information technology, renewable energy and energy conservation system, MEMS/nanotechnology | E31: Funds of $5-10K(INR 4 to 8 Lakhs) from Ministry of Micro, Small & Medium Enterprises (MSME) | F31: 10+ | G31: 2 | H31: 100000000 | I31: 37.5 | J31: 30 | K31: 16 | L31: 15 | M31: 20 | N31: 38000 | O31: 5 | P31: 2 | R31: MAHE Innovation & MUTBI 15-Year Ecosystem Performance Report (manipal.edu)
A32: MICA – Incubator | B32: Gujarat | C32: 2010 | D32: Communication service technologies, communication product technologies, communication equipment, applications tools for communication business | E32: Equity | F32: 30+ | G32: 0 | H32: 50000000 | I32: 27.5 | J32: 18 | K32: 16 | L32: 10 | M32: 115 | N32: 500 | O32: 4 | P32: 1 | R32: mica.ac.in, DST-NSTEDB, pitchbook.com, etc. | U32: Source includes PitchBook, which counts any portfolio liquidity/status change (incl. secondary sales, write-offs, shutdowns) as an 'exit' — NOT the strict IPO/M&A/LBO definition. Verified case studies (Villgro, NASSCOM 10,000 Startups, CIIE IIM-A) show PitchBook's loose exit count is roughly 15-20x the true IPO/M&A count. This figure is very likely overstated.
A33: NASSCOM 10,000 Startups | B33: Bengaluru, Noida, Gurugram, Kolkata, Navi Mumbai, Chennai, Hyderabad, Pune, Kochi, and Vizag. | C33: 2013 | G33: 45 | H33: 1000000000 | I33: 52.5 | J33: 200 | K33: 13 | L33: 100 | M33: 150 | N33: 3000 | O33: 5 | P33: 10 | R33: NASSCOM Official Portals (nasscom.in / 10000startups.com, pitchbook, Startup Haryana, State gc startup policy recs | U33: Source includes PitchBook, which counts any portfolio liquidity/status change (incl. secondary sales, write-offs, shutdowns) as an 'exit' — NOT the strict IPO/M&A/LBO definition. Verified case studies (Villgro, NASSCOM 10,000 Startups, CIIE IIM-A) show PitchBook's loose exit count is roughly 15-20x the true IPO/M&A count. This figure is very likely overstated. PitchBook shows 46 loose 'exits' (matches dataset's 45 almost exactly), but another investor database lists 'Number of Exits: 1' and a 2015 Inc42 article cites '6 of 64 startups' exited via acquisition (different snapshot year). The 45 figure is almost certainly the PitchBook broad-definition count, not strict IPO/M&A. RECOMMEND FLAGGING AS UNVERIFIED/LIKELY OVERSTATED; true figure is probably in the single digits.
A34: NDBI (NID Incubator) | B34: Ahmedabad, Bengaluru, Gandhinagar | C34: 2004 | D34: Young, design-focussed entrepreneurs | E34: via DIPP, through venture ready fund scheme | G34: 0 | H34: 50000000 | I34: 22.5 | J34: 23 | K34: 21 | L34: 10 | M34: 15 | N34: 13000 | O34: 4 | P34: 1 | R34: NDBI Official Portal (ndbiindia.org) & NID Main Site (nid.edu), ISTI Portal, DST-NSTEDB
A35: NITK-Science Technology Entrepreneurship Park | B35: Mangalore, Karnataka | C35: 1994 | D35: Information technology, electronics & robotics, multi-disciplinary technology integration, engineering design, and consultancy. | E35: Incubatees of startup units can avail Seed capital support through “Seed Support System to Startups at Incubators” a scheme of the Technology Development Board implemented at NITK-STEP. Four incuabtees are given seed capital support of $7K-$14K (INR5-10 Lakhs) per incubated startups, with the first instalment of support already released. | G35: 0 | H35: 50000000 | I35: 22.5 | J35: 20 | K35: 32 | L35: 10 | M35: 15 | N35: 6000 | O35: 4 | P35: 1 | R35: NITK-STEP Official Portal (step.nitk.ac.in), Department of Science & Technology (DST-NSTEDB) & MSME Disclosures
A36: NIT TREC-STEP | B36: NIT Campus, Tiruchirapalli | C36: 2004 | D36: Cleantech, IT, engineering, biotech | G36: 0 | H36: 150000000 | I36: 22.5 | J36: 23 | K36: 40 | L36: 25 | M36: 15 | N36: 7100 | O36: 5 | P36: 1 | R36: trecstep.com, ebn.eu, startupgrantsindia.com, DST_NSTEDB
A37: NSRCEL, IIM Bangalore | B37: Bengaluru | C37: 2002 | D37: Sector-agnostic (ecommerce, fintech, healthcare, FMCG, social enterprises, and cloud-based IT solutions) | E37: 5% Equity | F37: 57 | G37: 15 | H37: 500000000 | I37: 47.5 | J37: 150 | K37: 26 | L37: 30 | M37: 50 | N37: 1350 | O37: 6 | P37: 1 | R37: nsrcel.org, iimb.ac.in, pitchbook.com | U37: Duplicate of 'NSRCEL, IIM Bangalore' — same entity listed twice with CONFLICTING values (15 vs 1). Source for '15' is pitchbook.com, which counts ANY portfolio liquidity/status change as an 'exit,' not just IPO/M&A/LBO — likely inflated. The '1' figure is closer to the strict definition. Source includes PitchBook, which counts any portfolio liquidity/status change (incl. secondary sales, write-offs, shutdowns) as an 'exit' — NOT the strict IPO/M&A/LBO definition. Verified case studies (Villgro, NASSCOM 10,000 Startups, CIIE IIM-A) show PitchBook's loose exit count is roughly 15-20x the true IPO/M&A count. This figure is very likely overstated.
A38: Periyar Technology Business Incubator | B38: Tamil Nadu | C38: 2006 | D38: Herbal, health products, biotechnology, food processing, and agro ventures. | G38: 0 | H38: 50000000 | I38: 17.5 | J38: 18 | K38: 20 | L38: 10 | M38: 10 | N38: 5200 | O38: 5 | P38: 1 | R38: periyartbi.pmu.edu, DST-NSTEDB
A39: PSG-STEP | B39: Coimbatore | C39: 1998 | D39: ICT, electronics, and mechanical | E39: A Seed Fund Support Scheme has been constituted by PSG-STEP with support from Technology Development Board (TDB) & National Science & Technology Entrepreneurship Development Board (NSTEDB), Department of Science & Technology, Government of India to extend financial support to technology ventures to cater to the early stage requirements of startups. | F39: 36 | G39: 2 | H39: 150000000 | I39: 27.5 | J39: 32.5 | K39: 28 | L39: 20 | M39: 15 | N39: 8500 | O39: 5 | P39: 2 | R39: psgstep.org, psgtech.edu, Department of Science & Technology (DST-NSTEDB) Directory: Official government records verifying STEP status, "Best STEP" national award recognition
A40: Sardar Patel Technology Business Incubator | B40: Mumbai, Maharashtra | C40: 2015 | D40: Education, health, energy, livelihood and smart city technologies, IOT, ecommerce , innovative SaaS, big data, cloud computing, artificial intelligence, hybrid business models with technology at its core, social startups, women-led startups. | G40: 0 | H40: 200000000 | I40: 22.5 | J40: 28 | K40: 11 | L40: 15 | M40: 10 | N40: 5000 | O40: 4 | P40: 1 | R40: SP-TBI Official Portal (sptbi.com) & SPIT Site (spit.ac.in), Official records confirming NIDHI-TBI status, $1.4M (₹10+ Cr) NIDHI-SSS capital
...

Sheet Sheet2
A1: Incubator | B1: Number of Exits (Normalized) | C1: Direct Capital Deployed (Rs) (Normalized) | D1: Portfolio Quality (% startups that raised funding) (Normalized) | E1: Current Active Capacity (Normalized) | F1: Age & Operational Maturity (Normalized) | G1: Corporate Partnerships (Normalized) | H1: Investor Network (Normalized) | I1: Talent Pool & Recruitment (Normalized) | J1: Sectoral Expertise (Normalized) | K1: Geographic & Demographic Diversity (Normalized) | L1: FINAL SCORES | O1: Number of Exits | P1: Direct Capital Deployed (Rs) | Q1: Portfolio Quality (% startups that raised funding) | R1: Current Active Capacity | S1: Age & Operational Maturity | T1: Corporate Partnerships | U1: Investor Network | V1: Talent Pool & Recruitment | W1: Sectoral Expertise | X1: Geographic & Demographic Diversity
A2: Amity Innovation Incubator | B2: 0 | C2: 0.015353805 | D2: 0.096 | E2: 0.29752066 | F2: 0.35555556 | G2: 0.13265306 | H2: 0.084249084 | I2: 1 | J2: 0.42857143 | K2: 0 | L2: =(B2*15%+C2*12%+D2*12%+E2*12%+F2*8%+G2*10%+H2*10%+I2*8%+J2*7%+K2*6%)*100 -> 20.919959 | O2: 0 | P2: 250000000 | Q2: 13.5 | R2: 80 | S2: 18 | T2: 15 | U2: 50 | V2: 175000 | W2: 5 | X2: 1
A3: Amrita TBI, Amrita VishwaVidhyapeetham | B3: 0.022222222 | C3: 0.0086782377 | D3: 0.392 | E3: 0.17355372 | F3: 0.35555556 | G3: 0.081632653 | H3: 0.038461538 | I3: 0.14899713 | J3: 0.57142857 | K3: 0.22222222 | L3: =(B3*15%+C3*12%+D3*12%+E3*12%+F3*8%+G3*10%+H3*10%+I3*8%+J3*7%+K3*6%)*100 -> 17.794814 | O3: 1 | P3: 150000000 | Q3: 32 | R3: 50 | S3: 18 | T3: 10 | U3: 25 | V3: 26500 | W3: 6 | X3: 3
A4: BAIT-TBI (Bannari Amman Institute of Technology – Technology Business Incubator) | B4: 0 | C4: 0.0010680908 | D4: 0.16 | E4: 0.1322314 | F4: 0.37777778 | G4: 0.010204082 | H4: 0.0018315018 | I4: 0.083094556 | J4: 0.28571429 | K4: 0 | L4: =(B4*15%+C4*12%+D4*12%+E4*12%+F4*8%+G4*10%+H4*10%+I4*8%+J4*7%+K4*6%)*100 -> 9.3269285 | O4: 0 | P4: 36000000 | Q4: 17.5 | R4: 40 | S4: 19 | T4: 3 | U4: 5 | V4: 15000 | W4: 4 | X4: 1
A5: Bihar Entrepreneurs Association (BEA) | B5: 0 | C5: 0.0010013351 | D5: 0.04 | E5: 0.15289256 | F5: 0.28888889 | G5: 0.06122449 | H5: 0.010989011 | I5: 0.10601719 | J5: 0.42857143 | K5: 0 | L5: =(B5*15%+C5*12%+D5*12%+E5*12%+F5*8%+G5*10%+H5*10%+I5*8%+J5*7%+K5*6%)*100 -> 9.2081104 | O5: 0 | P5: 35000000 | Q5: 10 | R5: 45 | S5: 15 | T5: 8 | U5: 10 | V5: 19000 | W5: 5 | X5: 1
A6: Bio Incubator at C-CAMP | B6: 0.11111111 | C6: 0.052069426 | D6: 0.92 | E6: 0.29752066 | F6: 0.33333333 | G6: 0.18367347 | H6: 0.065934066 | I6: 0.28366762 | J6: 0.42857143 | K6: 0 | L6: =(B6*15%+C6*12%+D6*12%+E6*12%+F6*8%+G6*10%+H6*10%+I6*8%+J6*7%+K6*6%)*100 -> 27.333831 | O6: 5 | P6: 800000000 | Q6: 65 | R6: 80 | S6: 17 | T6: 20 | U6: 40 | V6: 50000 | W6: 5 | X6: 1
A7: CED | B7: 0 | C7: 0.0086782377 | D7: 0 | E7: 0.21487603 | F7: 1 | G7: 0.081632653 | H7: 0.0018315018 | I7: 0.28366762 | J7: 0.28571429 | K7: 0 | L7: =(B7*15%+C7*12%+D7*12%+E7*12%+F7*8%+G7*10%+H7*10%+I7*8%+J7*7%+K7*6%)*100 -> 15.786634 | O7: 0 | P7: 150000000 | Q7: 7.5 | R7: 60 | S7: 47 | T7: 10 | U7: 5 | V7: 50000 | W7: 4 | X7: 1
A8: Centre For Entrepreneurship and Development | B8: 0 | C8: 0.00033377837 | D8: 0 | E8: 0.11157025 | F8: 0.6 | G8: 0.030612245 | H8: 0.0018315018 | I8: 0.045845272 | J8: 0.28571429 | K8: 0.11111111 | L8: =(B8*15%+C8*12%+D8*12%+E8*12%+F8*8%+G8*10%+H8*10%+I8*8%+J8*7%+K8*6%)*100 -> 9.5007146 | O8: 0 | P8: 25000000 | Q8: 7.5 | R8: 35 | S8: 29 | T8: 5 | U8: 5 | V8: 8500 | W8: 4 | X8: 2
A9: CET – Technology Business Incubator | B9: 0 | C9: 0.0016688919 | D9: 0.16 | E9: 0.070247934 | F9: 0.42222222 | G9: 0.030612245 | H9: 0.0036630037 | I9: 0.025787966 | J9: 0.28571429 | K9: 0 | L9: =(B9*15%+C9*12%+D9*12%+E9*12%+F9*8%+G9*10%+H9*10%+I9*8%+J9*7%+K9*6%)*100 -> 8.7098359 | O9: 0 | P9: 45000000 | Q9: 17.5 | R9: 25 | S9: 21 | T9: 5 | U9: 6 | V9: 5000 | W9: 4 | X9: 1
A10: Center For Incubation and Business Acceleration | B10: 0 | C10: 0.0040053405 | D10: 0.32 | E10: 0.17355372 | F10: 0.26666667 | G10: 0.06122449 | H10: 0.02014652 | I10: 0.054441261 | J10: 0.28571429 | K10: 0.22222222 | L10: =(B10*15%+C10*12%+D10*12%+E10*12%+F10*8%+G10*10%+H10*10%+I10*8%+J10*7%+K10*6%)*100 -> 12.686616 | O10: 0 | P10: 80000000 | Q10: 27.5 | R10: 50 | S10: 14 | T10: 8 | U10: 15 | V10: 10000 | W10: 4 | X10: 3
A11: CIIE IIM-A | B11: 0.77777778 | C11: 0.19893191 | D11: 0.88 | E11: 0.38016529 | F11: 0.48888889 | G11: 0.28571429 | H11: 0.17582418 | I11: 0.054441261 | J11: 0.57142857 | K11: 0.44444444 | L11: =(B11*15%+C11*12%+D11*12%+E11*12%+F11*8%+G11*10%+H11*10%+I11*8%+J11*7%+K11*6%)*100 -> 44.804526 | O11: 35 | P11: 3000000000 | Q11: 62.5 | R11: 100 | S11: 24 | T11: 30 | U11: 100 | V11: 10000 | W11: 6 | X11: 5
A12: Coimbatore Innovation and Business Incubator | B12: 0 | C12: 0.012016021 | D12: 0.48 | E12: 0.21487603 | F12: 0.22222222 | G12: 0.18367347 | H12: 0.038461538 | I12: 0.083094556 | J12: 0.42857143 | K12: 0.11111111 | L12: =(B12*15%+C12*12%+D12*12%+E12*12%+F12*8%+G12*10%+H12*10%+I12*8%+J12*7%+K12*6%)*100 -> 16.813256 | O12: 0 | P12: 200000000 | Q12: 37.5 | R12: 60 | S12: 12 | T12: 20 | U12: 25 | V12: 15000 | W12: 5 | X12: 2
A13: Composites Technology Park | B13: 0 | C13: 0.0010013351 | D13: 0.08 | E13: 0 | F13: 0.48888889 | G13: 0.081632653 | H13: 0 | I13: 0.025787966 | J13: 0.14285714 | K13: 0 | L13: =(B13*15%+C13*12%+D13*12%+E13*12%+F13*8%+G13*10%+H13*10%+I13*8%+J13*7%+K13*6%)*100 -> 6.9057574 | O13: 0 | P13: 35000000 | Q13: 12.5 | R13: 8 | S13: 24 | T13: 10 | U13: 4 | V13: 5000 | W13: 3 | X13: 1
... A117: AIC RAISE | B117: 0 | C117: 0.002670227 | D117: 0.168 | E117: 0.02892562 | F117: 0.066666667 | G117: 0.040816327 | H117: 0.010989011 | I117: 0.065902579 | J117: 0.14285714 | K117: 0.11111111 | L117: =(B117*15%+C117*12%+D117*12%+E117*12%+F117*8%+G117*10%+H117*10%+I117*8%+J117*7%+K117*6%)*100 -> 5.6404242 | O117: 0 | P117: 60000000 | Q117: 18 | R117: 15 | S117: 5 | T117: 6 | U117: 10 | V117: 12000 | W117: 3 | X117: 2

Sheet Sheet3
A1: Incubator | B1: Final Score
A2: =Sheet2!A33 -> NASSCOM 10,000 Startups | B2: =Sheet2!L33 -> 57.689869
A3: =Sheet2!A11 -> CIIE IIM-A | B3: =Sheet2!L11 -> 44.804526
A4: =Sheet2!A99 -> T-Hub | B4: =Sheet2!L99 -> 43.664806
A5: =Sheet2!A101 -> SINE (Society for Innovation & Entrepreneurship) - IIT Bombay | B5: =Sheet2!L101 -> 42.152851
A6: =Sheet2!A21 -> IIT Madras Incubation Cell (IITMIC) | B6: =Sheet2!L21 -> 39.456227
A7: =Sheet2!A17 -> Foundation For Innovation And Technology Transfer, IIT-D | B7: =Sheet2!L17 -> 35.266202
A8: =Sheet2!A29 -> Life Science Incubator at IKP Knowledge Park | B8: =Sheet2!L29 -> 33.433264
A9: =Sheet2!A37 -> NSRCEL, IIM Bangalore | B9: =Sheet2!L37 -> 32.111104
A10: =Sheet2!A28 -> Kerala Startup Mission KSUM | B10: =Sheet2!L28 -> 31.865273
A11: =Sheet2!A102 -> Maker Village - Kochi | B11: =Sheet2!L102 -> 31.039531
A12: =Sheet2!A6 -> Bio Incubator at C-CAMP | B12: =Sheet2!L6 -> 27.333831
A13: =Sheet2!A19 -> IIM Calcutta Innovation Park | B13: =Sheet2!L19 -> 25.42607
A14: =Sheet2!A62 -> Venture Center | B14: =Sheet2!L62 -> 24.577254
A15: =Sheet2!A87 -> STEP- IIT Roorkee | B15: =Sheet2!L87 -> 24.033742
A16: =Sheet2!A79 -> MITCON Biotechnology Business Incubation Centre | B16: =Sheet2!L79 -> 23.52626
A17: =Sheet2!A44 -> SIDBI Innovation & Incubation Centre, IIT Kanpur | B17: =Sheet2!L44 -> 23.49925
A18: =Sheet2!A22 -> IIIT-H Foundation | B18: =Sheet2!L22 -> 21.450476
A19: =Sheet2!A2 -> Amity Innovation Incubator | B19: =Sheet2!L2 -> 20.919959
A20: =Sheet2!A100 -> IKP Eden | B20: =Sheet2!L100 -> 20.390061
A21: TBI BITS Pilani | B21: =Sheet2!L51 -> 20.244647
A22: =Sheet2!A84 -> Science & Technology Entrepreneurs Park | B22: =Sheet2!L84 -> 18.738351
A23: =Sheet2!A16 -> DLabs | B23: =Sheet2!L16 -> 17.909923
A24: =Sheet2!A3 -> Amrita TBI, Amrita VishwaVidhyapeetham | B24: =Sheet2!L3 -> 17.794814
A25: =Sheet2!A55 -> TIETS, IIT Kgp | B25: =Sheet2!L55 -> 17.774135
A26: =Sheet2!A64 -> Wadhwani Centre For Entrepreneurship Development | B26: =Sheet2!L64 -> 17.771541
A27: =Sheet2!A86 -> Society for Innovation & Development (SID) | B27: =Sheet2!L86 -> 17.713004
A28: =Sheet2!A20 -> IIT Hyderabad Incubator | B28: =Sheet2!L20 -> 17.07932
A29: =Sheet2!A31 -> Manipal University Technology Business Incubator | B29: =Sheet2!L31 -> 17.075985
A30: =Sheet2!A78 -> MITCON Biopharma | B30: =Sheet2!L78 -> 16.98096
A31: =Sheet2!A12 -> Coimbatore Innovation and Business Incubator | B31: =Sheet2!L12 -> 16.813256
A32: =Sheet2!A39 -> PSG-STEP | B32: =Sheet2!L39 -> 16.519533
A33: =Sheet2!A63 -> Villgro Innovations Foundation | B33: =Sheet2!L63 -> 16.489746
A34: =Sheet2!A27 -> International Centre for Entrepreneurship and Technology | B34: =Sheet2!L27 -> 16.456549
A35: =Sheet2!A56 -> Technology Business Incubator, KIIT University | B35: =Sheet2!L56 -> 16.422656
A36: =Sheet2!A36 -> NIT TREC-STEP | B36: =Sheet2!L36 -> 16.334479
A37: =Sheet2!A42 -> Rural Technology and Business Incubator (RTBI) | B37: =Sheet2!L42 -> 16.035603
A38: =Sheet2!A7 -> CED | B38: =Sheet2!L7 -> 15.786634
A39: =Sheet2!A30 -> Malviya Centre for Innovation Incubation & Entrepreneurship, IIT BHU | B39: =Sheet2!L30 -> 15.204607
A40: =Sheet2!A43 -> Science & Technology Park, University of Pune | B40: =Sheet2!L43 -> 15.136611
...
